Workbook

Sheet リードタイム
A1: 種類コード | B1: 種類名 | C1: 設計工数（日） | D1: 製作工数（日）
A2: Die | B2: Die（金型） | C2: 30 | D2: 45
A3: TP | B3: TP（トリム型） | C3: 20 | D3: 30
A4: Tem | B4: Tem（ベント落とし） | C4: 15 | D4: 20
A5: Mill | B5: Mill（加工治具） | C5: 15 | D5: 25
A6: GC | B6: GC（切断治具） | C6: 15 | D6: 20
A7: Ins | B7: Ins（検査治具） | C7: 10 | D7: 15
A8: S | B8: S（強度試験治具） | C8: 10 | D8: 15
A9: Other | B9: Other（その他） | C9: 10 | D9: 15

Sheet 製品マスター
A1: 受注番号 | B1: 製品品番 | C1: 製作アイテム | D1: 種類 | E1: 設計担当者 | F1: 製作担当者 | G1: 依頼担当者名 | H1: 依頼部署 | I1: 納期 | J1: 見積り金額 | K1: 備考
A2: 30 | B2: 0.5882352941176471 | D2: 売上予定 | J2: 14371145 | K2: 0.17910354
A3: 1927 | B3: 079618-1380スリーブ | C3: 型番ピン４ | D3: Die | J3: 10240
A4: 29 | B4: 1 | J4: 14117160 | K4: 2025.11.3
A5: 41 | B5: 1 | J5: 17114285 | K5: 2025.11.3
A6: 47 | B6: 1 | J6: 16120281 | K6: 2025.12.8
A7: 70 | B7: 1 | J7: 15930669 | K7: 2026.1.9
A8: 41 | B8: 1 | D8: 売上予定 | J8: 13033450 | K8: 0.99999386
A9: 40 | B9: 1 | C9: 159409 | D9: 売上予定 | J9: 9395331 | K9: 1
A10: 1613 | B10: 11-652 | C10: ﾄﾘﾑ型_新作 | D10: TP | I10: 46141.625 | J10: 2316101 | K10: SRK-TN向け 部品点数多
A11: 2000 | B11: 11-658B-1 | C11: ﾄﾘﾑ型_新作 | D11: TP | I11: 46156.625 | K11: SRK-TN向け
A12: 2001 | B12: 11-661B-1 | C12: ﾄﾘﾑ型_新作 | D12: TP | I12: 46156.625 | K12: SRK-TN向け
A13: 1974 | B13: 11220W080P-13 | C13: 金型_修理 | D13: Die | J13: 78164
A14: 1203 | B14: 11220W080P-13 | C14: 切断治具_改造 | D14: GC | I14: 46084.625 | J14: 20030
A15: 1792 | B15: 11220W090P-13 | C15: 金型_修正 | D15: Die | I15: 45970.625 | J15: 225170 | K15: 押ﾋﾟﾝ孔ﾊﾞﾘ修正(47,850) 分流子押ﾋﾟﾝ追加(177,320)
A16: 1919 | B16: 12-382 | C16: 更新3次型_修正 | D16: Die | J16: 56560
A17: 1927 | B17: 12-382 | C17: 更新2次型_ﾛｯﾄﾏｰｸﾋﾟﾝ | D17: Die | J17: 5756.6
A18: 1919 | B18: 12-382B-1 | C18: 更新3次型（前型八州） | D18: Die | I18: 45988.625 | J18: 4300000
A19: 1786 | B19: 122ｓ | C19: A型_部品 | D19: Die | J19: 263008 | K19: 3/24現 タイマ処理中
A20: 1901 | B20: 12305-B2430 | C20: ﾄﾘﾑ型_新作 | D20: TP | I20: 45988.625 | J20: 1187678
A21: 1902 | B21: 12305-B2430 | C21: 切断治具_新作 | D21: GC | I21: 45988.625 | J21: 247363
A22: 1903 | B22: 12305-B2430 | C22: ﾍﾞﾝﾄ落とし_新作 | D22: Tem | I22: 45988.625 | J22: 154743
A23: 1924 | B23: 12305-B2430 | C23: 強度試験治具 | D23: S | I23: 45990.625 | J23: 97410
A24: 1900 | B24: 12305-B2430 | C24: 加工治具_新作 | D24: Mill | I24: 45960.625 | J24: 624987 | K24: S500平置き仕様
A25: 1990 | B25: 12305-B2430 | C25: 金型_改造 | D25: Die | J25: 74087 | K25: 金型のポカヨケ移動工事(溶接埋め→新しい位置に掘り込み)
A26: 1927 | B26: 12306-B2150 | C26: 更新7,8,9次型_ﾛｯﾄﾏｰｸﾋﾟﾝ | D26: Die | J26: 24075 | K26: 技術依頼分
A27: 713 | B27: 123s | C27: 固定2ｘ12 | D27: Die | J27: 148800
A28: 714 | B28: 123s | C28: 固定3ｘ12 | D28: Die | J28: 174000
A29: 717 | B29: 123s | C29: 可動2-13 x12 | D29: Die | J29: 195600
A30: 404 | B30: 1340ｓ | C30: ﾄﾘﾑ型_部品 | D30: TP | J30: 89473 | K30: 下刃
A31: 258 | B31: 1380ｓ | C31: ﾄﾘﾑ型_部品 | D31: TP | J31: 72760 | K31: W/C渋滞待ち
A32: 1853 | B32: 14-244 | C32: ﾄﾘﾑ型_新作 | D32: TP | I32: 45929.625 | J32: 2300000
A33: 1854 | B33: 14-247 | C33: ﾄﾘﾑ型_部品 | D33: TP | J33: 103833 | K33: SRK-TN向け
B34: 14-250 | C34: ﾄﾘﾑ型_新作 | D34: TP | J34: 2300000 | K34: SRK-TN向け
B35: 14-253 | C35: ﾄﾘﾑ型_新作 | D35: TP | J35: 2300000 | K35: SRK-TN向け
A36: 1906 | B36: 14-260 | C36: 切断治具_改造 | D36: GC | J36: 57716
A37: 1906 | B37: 14-260 Inner(ﾀｺﾏ) | C37: 切断治具_新作 | D37: GC | I37: 45988.625 | J37: 184425
A38: 1907 | B38: 14-260 Inner(ﾀｺﾏ) | C38: ﾍﾞﾝﾄ落とし_新作 | D38: Tem | I38: 45988.625 | J38: 108798
A39: 1905 | B39: 14-260 Inner(ﾀｺﾏ) | C39: ﾄﾘﾑ型_新作 | D39: TP | I39: 45988.625 | J39: 896489 | K39: 外周PLはVLで拾う
A40: 1927 | B40: 14-260A-1(UN-438) | C40: 更新次型_ﾛｯﾄﾏｰｸﾋﾟﾝ | D40: Die | J40: 14980 | K40: 技術依頼分
...

Sheet 進捗管理
A1: No | B1: 受注番号 | C1: 製品品番 | D1: 製作アイテム | E1: 種類 | F1: 設計担当 | G1: 製作担当 | H1: 依頼部署 | I1: 納期 | J1: 設計開始日 | K1: 設計完了日 | L1: 設計ST | M1: 制作開始日 | N1: 制作完了日 | O1: 制作ST | P1: 全体ST | Q1: 備考 | R1: 3月 | S1: 2 | T1: 3 | U1: 4 | V1: 5 | W1: 6 | X1: 7 | Y1: 8 | Z1: 9 | AA1: 10 | AB1: 11 | AC1: 12 | AD1: 13 | AE1: 14 | AF1: 15 | AG1: 16 | AH1: 17 | AI1: 18 | AJ1: 19 | AK1: 20 | AL1: 21 | AM1: 22 | AN1: 23 | AO1: 24 | AP1: 25 | AQ1: 26 | AR1: 27 | AS1: 28 | AT1: 29 | AU1: 30 | AV1: 31 | AW1: 4月 | AX1: 2 | AY1: 3 | AZ1: 4 | BA1: 5 | BB1: 6 | BC1: 7 | BD1: 8 | BE1: 9 | BF1: 10 | BG1: 11 | BH1: 12 | BI1: 13 | BJ1: 14 | BK1: 15 | BL1: 16 | BM1: 17 | BN1: 18 | BO1: 19 | BP1: 20 | BQ1: 21 | BR1: 22 | BS1: 23 | BT1: 24 | BU1: 25 | BV1: 26 | BW1: 27 | BX1: 28 | BY1: 29 | BZ1: 30 | CA1: 5月 | CB1: 2 | CC1: 3 | CD1: 4 | CE1: 5 | CF1: 6 | CG1: 7 | CH1: 8 | CI1: 9 | CJ1: 10 | CK1: 11 | CL1: 12 | CM1: 13 | CN1: 14 | CO1: 15 | CP1: 16 | CQ1: 17 | CR1: 18 | CS1: 19 | CT1: 20 | CU1: 21 | CV1: 22 | CW1: 23 | CX1: 24 | CY1: 25 | CZ1: 26 | DA1: 27 | DB1: 28 | DC1: 29 | DD1: 30 | DE1: 31 | DF1: 6月 | DG1: 2 | DH1: 3 | DI1: 4 | DJ1: 5 | DK1: 6 | DL1: 7 | DM1: 8 | DN1: 9 | DO1: 10 | DP1: 11 | DQ1: 12 | DR1: 13 | DS1: 14 | DT1: 15 | DU1: 16 | DV1: 17 | DW1: 18 | DX1: 19 | DY1: 20 | DZ1: 21 | EA1: 22 | EB1: 23 | EC1: 24 | ED1: 25 | EE1: 26 | EF1: 27 | EG1: 28 | EH1: 29 | EI1: 30 | EJ1: 7月 | EK1: 2 | EL1: 3 | EM1: 4 | EN1: 5 | EO1: 6 | EP1: 7 | EQ1: 8 | ER1: 9 | ES1: 10 | ET1: 11 | EU1: 12 | EV1: 13 | EW1: 14 | EX1: 15 | EY1: 16 | EZ1: 17 | FA1: 18 | FB1: 19 | FC1: 20 | FD1: 21 | FE1: 22 | FF1: 23 | FG1: 24 | FH1: 25 | FI1: 26 | FJ1: 27 | FK1: 28 | FL1: 29 | FM1: 30 | FN1: 31 | FO1: 8月 | FP1: 2 | FQ1: 3 | FR1: 4 | FS1: 5 | FT1: 6 | FU1: 7 | FV1: 8 | FW1: 9 | FX1: 10 | FY1: 11 | FZ1: 12 | GA1: 13 | GB1: 14 | GC1: 15 | GD1: 16 | GE1: 17 | GF1: 18 | GG1: 19 | GH1: 20 | GI1: 21 | GJ1: 22 | GK1: 23 | GL1: 24 | GM1: 25 | GN1: 26 | GO1: 27 | GP1: 28 | GQ1: 29 | GR1: 30 | GS1: 31 | GT1: 9月 | GU1: 2 | GV1: 3 | GW1: 4 | GX1: 5 | GY1: 6 | GZ1: 7 | HA1: 8 | HB1: 9 | HC1: 10 | HD1: 11 | HE1: 12 | HF1: 13 | HG1: 14 | HH1: 15 | HI1: 16 | HJ1: 17 | HK1: 18 | HL1: 19 | HM1: 20 | HN1: 21 | HO1: 22 | HP1: 23 | HQ1: 24 | HR1: 25 | HS1: 26 | HT1: 27 | HU1: 28 | HV1: 29 | HW1: 30 | HX1: 10月 | HY1: 2 | HZ1: 3 | IA1: 4 | IB1: 5 | IC1: 6 | ID1: 7 | IE1: 8 | IF1: 9 | IG1: 10 | IH1: 11 | II1: 12 | IJ1: 13 | IK1: 14 | IL1: 15 | IM1: 16 | IN1: 17 | IO1: 18 | IP1: 19 | IQ1: 20 | IR1: 21 | IS1: 22 | IT1: 23 | IU1: 24 | IV1: 25 | IW1: 26 | IX1: 27 | IY1: 28 | IZ1: 29 | JA1: 30 | JB1: 31 | JC1: 11月 | JD1: 2 | JE1: 3 | JF1: 4 | JG1: 5 | JH1: 6 | JI1: 7 | JJ1: 8 | JK1: 9 | JL1: 10 | JM1: 11 | JN1: 12 | JO1: 13 | JP1: 14 | JQ1: 15 | JR1: 16 | JS1: 17 | JT1: 18 | JU1: 19 | JV1: 20 | JW1: 21 | JX1: 22 | JY1: 23 | JZ1: 24 | KA1: 25 | KB1: 26 | KC1: 27 | KD1: 28 | KE1: 29 | KF1: 30 | KG1: 12月 | KH1: 2 | KI1: 3 | KJ1: 4 | KK1: 5 | KL1: 6 | KM1: 7 | KN1: 8 | KO1: 9 | KP1: 10 | KQ1: 11 | KR1: 12 | KS1: 13 | KT1: 14 | KU1: 15 | KV1: 16 | KW1: 17 | KX1: 18 | KY1: 19 | KZ1: 20 | LA1: 21 | LB1: 22 | LC1: 23 | LD1: 24 | LE1: 25 | LF1: 26 | LG1: 27 | LH1: 28 | LI1: 29 | LJ1: 30 | LK1: 31 | LL1: 1月 | LM1: 2 | LN1: 3 | LO1: 4 | LP1: 5 | LQ1: 6 | LR1: 7 | LS1: 8 | LT1: 9 | LU1: 10 | LV1: 11 | LW1: 12 | LX1: 13 | LY1: 14 | LZ1: 15 | MA1: 16 | MB1: 17 | MC1: 18 | MD1: 19 | ME1: 20 | MF1: 21 | MG1: 22 | MH1: 23 | MI1: 24 | MJ1: 25 | MK1: 26 | ML1: 27 | MM1: 28 | MN1: 29 | MO1: 30 | MP1: 31 | MQ1: 2月 | MR1: 2 | MS1: 3 | MT1: 4 | MU1: 5 | MV1: 6 | MW1: 7 | MX1: 8 | MY1: 9 | MZ1: 10 | NA1: 11 | NB1: 12 | NC1: 13 | ND1: 14 | NE1: 15 | NF1: 16 | NG1: 17 | NH1: 18 | NI1: 19 | NJ1: 20 | NK1: 21 | NL1: 22 | NM1: 23 | NN1: 24 | NO1: 25 | NP1: 26 | NQ1: 27 | NR1: 28
A2: 1 | B2: 30 | C2: 0.5882352941176471 | E2: 売上予定 | K2: =IF(OR(J2="",E2=""),"",J2+IFERROR(VLOOKUP(E2,リードタイム!$A$2:$C$9,3,FALSE),0)) | L2: 未着手 | N2: =IF(OR(M2="",E2=""),"",M2+IFERROR(VLOOKUP(E2,リードタイム!$A$2:$D$9,4,FALSE),0)) | O2: 未着手 | P2: 未着手 | Q2: 0.17910354
A3: 1 | B3: 1927 | C3: 079618-1380スリーブ | D3: 型番ピン４ | E3: Die | K3: =IF(OR(J3="",E3=""),"",J3+IFERROR(VLOOKUP(E3,リードタイム!$A$2:$C$9,3,FALSE),0)) | L3: 未着手 | N3: =IF(OR(M3="",E3=""),"",M3+IFERROR(VLOOKUP(E3,リードタイム!$A$2:$D$9,4,FALSE),0)) | O3: 未着手 | P3: 未着手
A4: 1 | B4: 29 | C4: 1 | K4: =IF(OR(J4="",E4=""),"",J4+IFERROR(VLOOKUP(E4,リードタイム!$A$2:$C$9,3,FALSE),0)) | L4: 完了 | N4: =IF(OR(M4="",E4=""),"",M4+IFERROR(VLOOKUP(E4,リードタイム!$A$2:$D$9,4,FALSE),0)) | O4: 完了 | P4: 制作完了 | Q4: 2025.11.3
A5: 2 | B5: 41 | C5: 1 | K5: =IF(OR(J5="",E5=""),"",J5+IFERROR(VLOOKUP(E5,リードタイム!$A$2:$C$9,3,FALSE),0)) | L5: 完了 | N5: =IF(OR(M5="",E5=""),"",M5+IFERROR(VLOOKUP(E5,リードタイム!$A$2:$D$9,4,FALSE),0)) | O5: 完了 | P5: 制作完了 | Q5: 2025.11.3
A6: 3 | B6: 47 | C6: 1 | K6: =IF(OR(J6="",E6=""),"",J6+IFERROR(VLOOKUP(E6,リードタイム!$A$2:$C$9,3,FALSE),0)) | L6: 完了 | N6: =IF(OR(M6="",E6=""),"",M6+IFERROR(VLOOKUP(E6,リードタイム!$A$2:$D$9,4,FALSE),0)) | O6: 完了 | P6: 制作完了 | Q6: 2025.12.8
A7: 4 | B7: 70 | C7: 1 | K7: =IF(OR(J7="",E7=""),"",J7+IFERROR(VLOOKUP(E7,リードタイム!$A$2:$C$9,3,FALSE),0)) | L7: 完了 | N7: =IF(OR(M7="",E7=""),"",M7+IFERROR(VLOOKUP(E7,リードタイム!$A$2:$D$9,4,FALSE),0)) | O7: 完了 | P7: 制作完了 | Q7: 2026.1.9
A8: 5 | B8: 41 | C8: 1 | E8: 売上予定 | K8: =IF(OR(J8="",E8=""),"",J8+IFERROR(VLOOKUP(E8,リードタイム!$A$2:$C$9,3,FALSE),0)) | L8: 未着手 | N8: =IF(OR(M8="",E8=""),"",M8+IFERROR(VLOOKUP(E8,リードタイム!$A$2:$D$9,4,FALSE),0)) | O8: 未着手 | P8: 未着手 | Q8: 0.99999386
A9: 6 | B9: 40 | C9: 1 | D9: 159409 | E9: 売上予定 | K9: =IF(OR(J9="",E9=""),"",J9+IFERROR(VLOOKUP(E9,リードタイム!$A$2:$C$9,3,FALSE),0)) | L9: 未着手 | N9: =IF(OR(M9="",E9=""),"",M9+IFERROR(VLOOKUP(E9,リードタイム!$A$2:$D$9,4,FALSE),0)) | O9: 未着手 | P9: 未着手 | Q9: 1
A10: 1 | B10: 1613 | C10: 11-652 | D10: ﾄﾘﾑ型_新作 | E10: TP | I10: 46141.625 | K10: =IF(OR(J10="",E10=""),"",J10+IFERROR(VLOOKUP(E10,リードタイム!$A$2:$C$9,3,FALSE),0)) | L10: 完了 | N10: =IF(OR(M10="",E10=""),"",M10+IFERROR(VLOOKUP(E10,リードタイム!$A$2:$D$9,4,FALSE),0)) | O10: 完了 | P10: 制作完了 | Q10: SRK-TN向け 部品点数多
A11: 1 | B11: 2000 | C11: 11-658B-1 | D11: ﾄﾘﾑ型_新作 | E11: TP | I11: 46156.625 | K11: =IF(OR(J11="",E11=""),"",J11+IFERROR(VLOOKUP(E11,リードタイム!$A$2:$C$9,3,FALSE),0)) | L11: 完了 | N11: =IF(OR(M11="",E11=""),"",M11+IFERROR(VLOOKUP(E11,リードタイム!$A$2:$D$9,4,FALSE),0)) | O11: 完了 | P11: 制作完了 | Q11: SRK-TN向け
A12: 1 | B12: 2001 | C12: 11-661B-1 | D12: ﾄﾘﾑ型_新作 | E12: TP | I12: 46156.625 | K12: =IF(OR(J12="",E12=""),"",J12+IFERROR(VLOOKUP(E12,リードタイム!$A$2:$C$9,3,FALSE),0)) | L12: 完了 | N12: =IF(OR(M12="",E12=""),"",M12+IFERROR(VLOOKUP(E12,リードタイム!$A$2:$D$9,4,FALSE),0)) | O12: 完了 | P12: 制作完了 | Q12: SRK-TN向け
A13: 1 | B13: 1974 | C13: 11220W080P-13 | D13: 金型_修理 | E13: Die | K13: =IF(OR(J13="",E13=""),"",J13+IFERROR(VLOOKUP(E13,リードタイム!$A$2:$C$9,3,FALSE),0)) | L13: 未着手 | N13: =IF(OR(M13="",E13=""),"",M13+IFERROR(VLOOKUP(E13,リードタイム!$A$2:$D$9,4,FALSE),0)) | O13: 未着手 | P13: 未着手
A14: 2 | B14: 1203 | C14: 11220W080P-13 | D14: 切断治具_改造 | E14: GC | I14: 46084.625 | K14: =IF(OR(J14="",E14=""),"",J14+IFERROR(VLOOKUP(E14,リードタイム!$A$2:$C$9,3,FALSE),0)) | L14: 完了 | N14: =IF(OR(M14="",E14=""),"",M14+IFERROR(VLOOKUP(E14,リードタイム!$A$2:$D$9,4,FALSE),0)) | O14: 完了 | P14: 出荷済
A15: 1 | B15: 1792 | C15: 11220W090P-13 | D15: 金型_修正 | E15: Die | I15: 45970.625 | K15: =IF(OR(J15="",E15=""),"",J15+IFERROR(VLOOKUP(E15,リードタイム!$A$2:$C$9,3,FALSE),0)) | L15: 完了 | N15: =IF(OR(M15="",E15=""),"",M15+IFERROR(VLOOKUP(E15,リードタイム!$A$2:$D$9,4,FALSE),0)) | O15: 完了 | P15: 出荷済 | Q15: 押ﾋﾟﾝ孔ﾊﾞﾘ修正(47,850) 分流子押ﾋﾟﾝ追加(177,320)
A16: 1 | B16: 1919 | C16: 12-382 | D16: 更新3次型_修正 | E16: Die | K16: =IF(OR(J16="",E16=""),"",J16+IFERROR(VLOOKUP(E16,リードタイム!$A$2:$C$9,3,FALSE),0)) | L16: 完了 | N16: =IF(OR(M16="",E16=""),"",M16+IFERROR(VLOOKUP(E16,リードタイム!$A$2:$D$9,4,FALSE),0)) | O16: 完了 | P16: 出荷済
A17: 2 | B17: 1927 | C17: 12-382 | D17: 更新2次型_ﾛｯﾄﾏｰｸﾋﾟﾝ | E17: Die | K17: =IF(OR(J17="",E17=""),"",J17+IFERROR(VLOOKUP(E17,リードタイム!$A$2:$C$9,3,FALSE),0)) | L17: 完了 | N17: =IF(OR(M17="",E17=""),"",M17+IFERROR(VLOOKUP(E17,リードタイム!$A$2:$D$9,4,FALSE),0)) | O17: 完了 | P17: 制作完了
A18: 1 | B18: 1919 | C18: 12-382B-1 | D18: 更新3次型（前型八州） | E18: Die | I18: 45988.625 | K18: =IF(OR(J18="",E18=""),"",J18+IFERROR(VLOOKUP(E18,リードタイム!$A$2:$C$9,3,FALSE),0)) | L18: 完了 | N18: =IF(OR(M18="",E18=""),"",M18+IFERROR(VLOOKUP(E18,リードタイム!$A$2:$D$9,4,FALSE),0)) | O18: 完了 | P18: 制作完了
A19: 1 | B19: 1786 | C19: 122ｓ | D19: A型_部品 | E19: Die | K19: =IF(OR(J19="",E19=""),"",J19+IFERROR(VLOOKUP(E19,リードタイム!$A$2:$C$9,3,FALSE),0)) | L19: 未着手 | N19: =IF(OR(M19="",E19=""),"",M19+IFERROR(VLOOKUP(E19,リードタイム!$A$2:$D$9,4,FALSE),0)) | O19: 未着手 | P19: 未着手 | Q19: 3/24現 タイマ処理中
A20: 1 | B20: 1901 | C20: 12305-B2430 | D20: ﾄﾘﾑ型_新作 | E20: TP | I20: 45988.625 | K20: =IF(OR(J20="",E20=""),"",J20+IFERROR(VLOOKUP(E20,リードタイム!$A$2:$C$9,3,FALSE),0)) | L20: 完了 | N20: =IF(OR(M20="",E20=""),"",M20+IFERROR(VLOOKUP(E20,リードタイム!$A$2:$D$9,4,FALSE),0)) | O20: 完了 | P20: 制作完了
A21: 2 | B21: 1902 | C21: 12305-B2430 | D21: 切断治具_新作 | E21: GC | I21: 45988.625 | K21: =IF(OR(J21="",E21=""),"",J21+IFERROR(VLOOKUP(E21,リードタイム!$A$2:$C$9,3,FALSE),0)) | L21: 完了 | N21: =IF(OR(M21="",E21=""),"",M21+IFERROR(VLOOKUP(E21,リードタイム!$A$2:$D$9,4,FALSE),0)) | O21: 完了 | P21: 制作完了
A22: 3 | B22: 1903 | C22: 12305-B2430 | D22: ﾍﾞﾝﾄ落とし_新作 | E22: Tem | I22: 45988.625 | K22: =IF(OR(J22="",E22=""),"",J22+IFERROR(VLOOKUP(E22,リードタイム!$A$2:$C$9,3,FALSE),0)) | L22: 完了 | N22: =IF(OR(M22="",E22=""),"",M22+IFERROR(VLOOKUP(E22,リードタイム!$A$2:$D$9,4,FALSE),0)) | O22: 完了 | P22: 制作完了
A23: 4 | B23: 1924 | C23: 12305-B2430 | D23: 強度試験治具 | E23: S | I23: 45990.625 | K23: =IF(OR(J23="",E23=""),"",J23+IFERROR(VLOOKUP(E23,リードタイム!$A$2:$C$9,3,FALSE),0)) | L23: 完了 | N23: =IF(OR(M23="",E23=""),"",M23+IFERROR(VLOOKUP(E23,リードタイム!$A$2:$D$9,4,FALSE),0)) | O23: 完了 | P23: 制作完了
A24: 5 | B24: 1900 | C24: 12305-B2430 | D24: 加工治具_新作 | E24: Mill | I24: 45960.625 | K24: =IF(OR(J24="",E24=""),"",J24+IFERROR(VLOOKUP(E24,リードタイム!$A$2:$C$9,3,FALSE),0)) | L24: 完了 | N24: =IF(OR(M24="",E24=""),"",M24+IFERROR(VLOOKUP(E24,リードタイム!$A$2:$D$9,4,FALSE),0)) | O24: 完了 | P24: 制作完了 | Q24: S500平置き仕様
A25: 6 | B25: 1990 | C25: 12305-B2430 | D25: 金型_改造 | E25: Die | K25: =IF(OR(J25="",E25=""),"",J25+IFERROR(VLOOKUP(E25,リードタイム!$A$2:$C$9,3,FALSE),0)) | L25: 未着手 | N25: =IF(OR(M25="",E25=""),"",M25+IFERROR(VLOOKUP(E25,リードタイム!$A$2:$D$9,4,FALSE),0)) | O25: 未着手 | P25: 未着手 | Q25: 金型のポカヨケ移動工事(溶接埋め→新しい位置に掘り込み)
A26: 1 | B26: 1927 | C26: 12306-B2150 | D26: 更新7,8,9次型_ﾛｯﾄﾏｰｸﾋﾟﾝ | E26: Die | K26: =IF(OR(J26="",E26=""),"",J26+IFERROR(VLOOKUP(E26,リードタイム!$A$2:$C$9,3,FALSE),0)) | L26: 完了 | N26: =IF(OR(M26="",E26=""),"",M26+IFERROR(VLOOKUP(E26,リードタイム!$A$2:$D$9,4,FALSE),0)) | O26: 完了 | P26: 出荷済 | Q26: 技術依頼分
A27: 1 | B27: 713 | C27: 123s | D27: 固定2ｘ12 | E27: Die | K27: =IF(OR(J27="",E27=""),"",J27+IFERROR(VLOOKUP(E27,リードタイム!$A$2:$C$9,3,FALSE),0)) | L27: 未着手 | N27: =IF(OR(M27="",E27=""),"",M27+IFERROR(VLOOKUP(E27,リードタイム!$A$2:$D$9,4,FALSE),0)) | O27: 未着手 | P27: 未着手
A28: 2 | B28: 714 | C28: 123s | D28: 固定3ｘ12 | E28: Die | K28: =IF(OR(J28="",E28=""),"",J28+IFERROR(VLOOKUP(E28,リードタイム!$A$2:$C$9,3,FALSE),0)) | L28: 未着手 | N28: =IF(OR(M28="",E28=""),"",M28+IFERROR(VLOOKUP(E28,リードタイム!$A$2:$D$9,4,FALSE),0)) | O28: 未着手 | P28: 未着手
A29: 3 | B29: 717 | C29: 123s | D29: 可動2-13 x12 | E29: Die | K29: =IF(OR(J29="",E29=""),"",J29+IFERROR(VLOOKUP(E29,リードタイム!$A$2:$C$9,3,FALSE),0)) | L29: 未着手 | N29: =IF(OR(M29="",E29=""),"",M29+IFERROR(VLOOKUP(E29,リードタイム!$A$2:$D$9,4,FALSE),0)) | O29: 未着手 | P29: 未着手
A30: 1 | B30: 404 | C30: 1340ｓ | D30: ﾄﾘﾑ型_部品 | E30: TP | K30: =IF(OR(J30="",E30=""),"",J30+IFERROR(VLOOKUP(E30,リードタイム!$A$2:$C$9,3,FALSE),0)) | L30: 未着手 | N30: =IF(OR(M30="",E30=""),"",M30+IFERROR(VLOOKUP(E30,リードタイム!$A$2:$D$9,4,FALSE),0)) | O30: 未着手 | P30: 未着手 | Q30: 下刃
A31: 1 | B31: 258 | C31: 1380ｓ | D31: ﾄﾘﾑ型_部品 | E31: TP | K31: =IF(OR(J31="",E31=""),"",J31+IFERROR(VLOOKUP(E31,リードタイム!$A$2:$C$9,3,FALSE),0)) | L31: 未着手 | N31: =IF(OR(M31="",E31=""),"",M31+IFERROR(VLOOKUP(E31,リードタイム!$A$2:$D$9,4,FALSE),0)) | O31: 未着手 | P31: 未着手 | Q31: W/C渋滞待ち
A32: 1 | B32: 1853 | C32: 14-244 | D32: ﾄﾘﾑ型_新作 | E32: TP | I32: 45929.625 | K32: =IF(OR(J32="",E32=""),"",J32+IFERROR(VLOOKUP(E32,リードタイム!$A$2:$C$9,3,FALSE),0)) | L32: 完了 | N32: =IF(OR(M32="",E32=""),"",M32+IFERROR(VLOOKUP(E32,リードタイム!$A$2:$D$9,4,FALSE),0)) | O32: 完了 | P32: 出荷済
A33: 1 | B33: 1854 | C33: 14-247 | D33: ﾄﾘﾑ型_部品 | E33: TP | K33: =IF(OR(J33="",E33=""),"",J33+IFERROR(VLOOKUP(E33,リードタイム!$A$2:$C$9,3,FALSE),0)) | L33: 完了 | N33: =IF(OR(M33="",E33=""),"",M33+IFERROR(VLOOKUP(E33,リードタイム!$A$2:$D$9,4,FALSE),0)) | O33: 完了 | P33: 出荷済 | Q33: SRK-TN向け
A34: 1 | C34: 14-250 | D34: ﾄﾘﾑ型_新作 | E34: TP | K34: =IF(OR(J34="",E34=""),"",J34+IFERROR(VLOOKUP(E34,リードタイム!$A$2:$C$9,3,FALSE),0)) | L34: 未着手 | N34: =IF(OR(M34="",E34=""),"",M34+IFERROR(VLOOKUP(E34,リードタイム!$A$2:$D$9,4,FALSE),0)) | O34: 未着手 | P34: 未着手 | Q34: SRK-TN向け
A35: 1 | C35: 14-253 | D35: ﾄﾘﾑ型_新作 | E35: TP | K35: =IF(OR(J35="",E35=""),"",J35+IFERROR(VLOOKUP(E35,リードタイム!$A$2:$C$9,3,FALSE),0)) | L35: 未着手 | N35: =IF(OR(M35="",E35=""),"",M35+IFERROR(VLOOKUP(E35,リードタイム!$A$2:$D$9,4,FALSE),0)) | O35: 未着手 | P35: 未着手 | Q35: SRK-TN向け
A36: 1 | B36: 1906 | C36: 14-260 | D36: 切断治具_改造 | E36: GC | K36: =IF(OR(J36="",E36=""),"",J36+IFERROR(VLOOKUP(E36,リードタイム!$A$2:$C$9,3,FALSE),0)) | L36: 完了 | N36: =IF(OR(M36="",E36=""),"",M36+IFERROR(VLOOKUP(E36,リードタイム!$A$2:$D$9,4,FALSE),0)) | O36: 完了 | P36: 出荷済
A37: 1 | B37: 1906 | C37: 14-260 Inner(ﾀｺﾏ) | D37: 切断治具_新作 | E37: GC | I37: 45988.625 | K37: =IF(OR(J37="",E37=""),"",J37+IFERROR(VLOOKUP(E37,リードタイム!$A$2:$C$9,3,FALSE),0)) | L37: 完了 | N37: =IF(OR(M37="",E37=""),"",M37+IFERROR(VLOOKUP(E37,リードタイム!$A$2:$D$9,4,FALSE),0)) | O37: 完了 | P37: 制作完了
A38: 2 | B38: 1907 | C38: 14-260 Inner(ﾀｺﾏ) | D38: ﾍﾞﾝﾄ落とし_新作 | E38: Tem | I38: 45988.625 | K38: =IF(OR(J38="",E38=""),"",J38+IFERROR(VLOOKUP(E38,リードタイム!$A$2:$C$9,3,FALSE),0)) | L38: 完了 | N38: =IF(OR(M38="",E38=""),"",M38+IFERROR(VLOOKUP(E38,リードタイム!$A$2:$D$9,4,FALSE),0)) | O38: 完了 | P38: 制作完了
A39: 3 | B39: 1905 | C39: 14-260 Inner(ﾀｺﾏ) | D39: ﾄﾘﾑ型_新作 | E39: TP | I39: 45988.625 | K39: =IF(OR(J39="",E39=""),"",J39+IFERROR(VLOOKUP(E39,リードタイム!$A$2:$C$9,3,FALSE),0)) | L39: 完了 | N39: =IF(OR(M39="",E39=""),"",M39+IFERROR(VLOOKUP(E39,リードタイム!$A$2:$D$9,4,FALSE),0)) | O39: 完了 | P39: 制作完了 | Q39: 外周PLはVLで拾う
A40: 1 | B40: 1927 | C40: 14-260A-1(UN-438) | D40: 更新次型_ﾛｯﾄﾏｰｸﾋﾟﾝ | E40: Die | K40: =IF(OR(J40="",E40=""),"",J40+IFERROR(VLOOKUP(E40,リードタイム!$A$2:$C$9,3,FALSE),0)) | L40: 完了 | N40: =IF(OR(M40="",E40=""),"",M40+IFERROR(VLOOKUP(E40,リードタイム!$A$2:$D$9,4,FALSE),0)) | O40: 完了 | P40: 出荷済 | Q40: 技術依頼分
...

Sheet 製品別サマリー
A1: 製品品番 | B1: アイテム数 | C1: 設計完了 | D1: 制作完了 | E1: 出荷済 | F1: 進捗率 | G1: 最終納期
A2: 0.5882352941176471 | B2: =COUNTIF(進捗管理!C:C,A2) -> 1 | C2: =COUNTIFS(進捗管理!C:C,A2,進捗管理!L:L,"完了") -> 0 | D2: =COUNTIFS(進捗管理!C:C,A2,進捗管理!O:O,"完了") -> 0 | E2: =COUNTIFS(進捗管理!C:C,A2,進捗管理!P:P,"出荷済") -> 0 | F2: =IF(B2=0,"",D2/B2) -> 0 | G2: =IFERROR(MAXIFS(進捗管理!I:I,進捗管理!C:C,A2),"")
A3: 079618-1380スリーブ | B3: =COUNTIF(進捗管理!C:C,A3) -> 1 | C3: =COUNTIFS(進捗管理!C:C,A3,進捗管理!L:L,"完了") -> 0 | D3: =COUNTIFS(進捗管理!C:C,A3,進捗管理!O:O,"完了") -> 0 | E3: =COUNTIFS(進捗管理!C:C,A3,進捗管理!P:P,"出荷済") -> 0 | F3: =IF(B3=0,"",D3/B3) -> 0 | G3: =IFERROR(MAXIFS(進捗管理!I:I,進捗管理!C:C,A3),"")
A4: 1 | B4: =COUNTIF(進捗管理!C:C,A4) -> 6 | C4: =COUNTIFS(進捗管理!C:C,A4,進捗管理!L:L,"完了") -> 4 | D4: =COUNTIFS(進捗管理!C:C,A4,進捗管理!O:O,"完了") -> 4 | E4: =COUNTIFS(進捗管理!C:C,A4,進捗管理!P:P,"出荷済") -> 0 | F4: =IF(B4=0,"",D4/B4) -> 0.66666667 | G4: =IFERROR(MAXIFS(進捗管理!I:I,進捗管理!C:C,A4),"")
A5: 11-652 | B5: =COUNTIF(進捗管理!C:C,A5) -> 1 | C5: =COUNTIFS(進捗管理!C:C,A5,進捗管理!L:L,"完了") -> 1 | D5: =COUNTIFS(進捗管理!C:C,A5,進捗管理!O:O,"完了") -> 1 | E5: =COUNTIFS(進捗管理!C:C,A5,進捗管理!P:P,"出荷済") -> 0 | F5: =IF(B5=0,"",D5/B5) -> 1 | G5: =IFERROR(MAXIFS(進捗管理!I:I,進捗管理!C:C,A5),"")
A6: 11-658B-1 | B6: =COUNTIF(進捗管理!C:C,A6) -> 1 | C6: =COUNTIFS(進捗管理!C:C,A6,進捗管理!L:L,"完了") -> 1 | D6: =COUNTIFS(進捗管理!C:C,A6,進捗管理!O:O,"完了") -> 1 | E6: =COUNTIFS(進捗管理!C:C,A6,進捗管理!P:P,"出荷済") -> 0 | F6: =IF(B6=0,"",D6/B6) -> 1 | G6: =IFERROR(MAXIFS(進捗管理!I:I,進捗管理!C:C,A6),"")
A7: 11-661B-1 | B7: =COUNTIF(進捗管理!C:C,A7) -> 1 | C7: =COUNTIFS(進捗管理!C:C,A7,進捗管理!L:L,"完了") -> 1 | D7: =COUNTIFS(進捗管理!C:C,A7,進捗管理!O:O,"完了") -> 1 | E7: =COUNTIFS(進捗管理!C:C,A7,進捗管理!P:P,"出荷済") -> 0 | F7: =IF(B7=0,"",D7/B7) -> 1 | G7: =IFERROR(MAXIFS(進捗管理!I:I,進捗管理!C:C,A7),"")
A8: 11220W080P-13 | B8: =COUNTIF(進捗管理!C:C,A8) -> 2 | C8: =COUNTIFS(進捗管理!C:C,A8,進捗管理!L:L,"完了") -> 1 | D8: =COUNTIFS(進捗管理!C:C,A8,進捗管理!O:O,"完了") -> 1 | E8: =COUNTIFS(進捗管理!C:C,A8,進捗管理!P:P,"出荷済") -> 1 | F8: =IF(B8=0,"",D8/B8) -> 0.5 | G8: =IFERROR(MAXIFS(進捗管理!I:I,進捗管理!C:C,A8),"")
A9: 11220W090P-13 | B9: =COUNTIF(進捗管理!C:C,A9) -> 1 | C9: =COUNTIFS(進捗管理!C:C,A9,進捗管理!L:L,"完了") -> 1 | D9: =COUNTIFS(進捗管理!C:C,A9,進捗管理!O:O,"完了") -> 1 | E9: =COUNTIFS(進捗管理!C:C,A9,進捗管理!P:P,"出荷済") -> 1 | F9: =IF(B9=0,"",D9/B9) -> 1 | G9: =IFERROR(MAXIFS(進捗管理!I:I,進捗管理!C:C,A9),"")
A10: 12-382 | B10: =COUNTIF(進捗管理!C:C,A10) -> 2 | C10: =COUNTIFS(進捗管理!C:C,A10,進捗管理!L:L,"完了") -> 2 | D10: =COUNTIFS(進捗管理!C:C,A10,進捗管理!O:O,"完了") -> 2 | E10: =COUNTIFS(進捗管理!C:C,A10,進捗管理!P:P,"出荷済") -> 1 | F10: =IF(B10=0,"",D10/B10) -> 1 | G10: =IFERROR(MAXIFS(進捗管理!I:I,進捗管理!C:C,A10),"")
A11: 12-382B-1 | B11: =COUNTIF(進捗管理!C:C,A11) -> 1 | C11: =COUNTIFS(進捗管理!C:C,A11,進捗管理!L:L,"完了") -> 1 | D11: =COUNTIFS(進捗管理!C:C,A11,進捗管理!O:O,"完了") -> 1 | E11: =COUNTIFS(進捗管理!C:C,A11,進捗管理!P:P,"出荷済") -> 0 | F11: =IF(B11=0,"",D11/B11) -> 1 | G11: =IFERROR(MAXIFS(進捗管理!I:I,進捗管理!C:C,A11),"")
A12: 122ｓ | B12: =COUNTIF(進捗管理!C:C,A12) -> 1 | C12: =COUNTIFS(進捗管理!C:C,A12,進捗管理!L:L,"完了") -> 0 | D12: =COUNTIFS(進捗管理!C:C,A12,進捗管理!O:O,"完了") -> 0 | E12: =COUNTIFS(進捗管理!C:C,A12,進捗管理!P:P,"出荷済") -> 0 | F12: =IF(B12=0,"",D12/B12) -> 0 | G12: =IFERROR(MAXIFS(進捗管理!I:I,進捗管理!C:C,A12),"")
A13: 12305-B2430 | B13: =COUNTIF(進捗管理!C:C,A13) -> 6 | C13: =COUNTIFS(進捗管理!C:C,A13,進捗管理!L:L,"完了") -> 5 | D13: =COUNTIFS(進捗管理!C:C,A13,進捗管理!O:O,"完了") -> 5 | E13: =COUNTIFS(進捗管理!C:C,A13,進捗管理!P:P,"出荷済") -> 0 | F13: =IF(B13=0,"",D13/B13) -> 0.83333333 | G13: =IFERROR(MAXIFS(進捗管理!I:I,進捗管理!C:C,A13),"")
... A182: ﾛｰﾀｰﾊﾌﾞ | B182: =COUNTIF(進捗管理!C:C,A182) -> 4 | C182: =COUNTIFS(進捗管理!C:C,A182,進捗管理!L:L,"完了") -> 1 | D182: =COUNTIFS(進捗管理!C:C,A182,進捗管理!O:O,"完了") -> 1 | E182: =COUNTIFS(進捗管理!C:C,A182,進捗管理!P:P,"出荷済") -> 0 | F182: =IF(B182=0,"",D182/B182) -> 0.25 | G182: =IFERROR(MAXIFS(進捗管理!I:I,進捗管理!C:C,A182),"")

Sheet 使い方
A1: 金型技術 製作進捗管理 — 使い方
A3: ■ 進捗管理シート（メイン）— データもガントチャートも1シートに統合
A4: A〜H列: 基本情報を入力（受注番号・品番・種類・担当者・納期）
A5: I列: 設計開始日を入力 → J列（設計完了日）が自動計算される
A6: L列: 制作開始日を入力 → M列（制作完了日）が自動計算される
A7: K/N/O列: ステータスをドロップダウンから選択
A8: Q列以降: ガントチャート（自動表示。触らなくてOK）
A10: ■ ガントチャートの見方
A11: 紫バー = 設計期間（I列〜J列）
A12: 水色バー = 制作期間（L列〜M列）
A13: 赤い縦線 = 今日の日付
A15: ■ ソートについて
... A26: GC=15/20, Ins=10/15, S=10/15, Other=10/15
